<?xml version="1.0"?>
<sdf version="1.9">
  <model name="x500">
    <pose>0 0 0.3 0 0 0</pose>
    <link name="base_link">
      <inertial>
        <mass>1.5</mass>
        <inertia>
          <ixx>0.029125</ixx>
          <iyy>0.029125</iyy>
          <izz>0.055225</izz>
        </inertia>
      </inertial>
      <visual name="base_visual">
        <geometry>
          <mesh>
            <uri>https://fuel.gazebosim.org/1.0/PX4/models/x500/meshes/x500_base.dae</uri>
            <scale>1.2 1.2 1.2</scale>
          </mesh>
        </geometry>
      </visual>
      <collision name="base_collision">
        <geometry>
          <box>
            <size>0.47 0.47 0.11</size>
          </box>
        </geometry>
      </collision>
    </link>

    <link name="rotor_0"><pose>0.13 -0.22 0.023 0 0 0</pose><inertial><mass>0.005</mass><inertia><ixx>9.75e-07</ixx><iyy>0.0001667</iyy><izz>0.0001676</izz></inertia></inertial><visual name="visual"><geometry><mesh><uri>https://fuel.gazebosim.org/1.0/PX4/models/x500/meshes/rotor.dae</uri><scale>1 1 1</scale></mesh></geometry></visual><collision name="collision"><geometry><cylinder><radius>0.128</radius><length>0.005</length></cylinder></geometry></collision></link>
    <joint name="rotor_0_joint" type="revolute"><parent>base_link</parent><child>rotor_0</child><axis><xyz>0 0 1</xyz></axis></joint>

    <link name="rotor_1"><pose>-0.13 0.2 0.023 0 0 0</pose><inertial><mass>0.005</mass><inertia><ixx>9.75e-07</ixx><iyy>0.0001667</iyy><izz>0.0001676</izz></inertia></inertial><visual name="visual"><geometry><mesh><uri>https://fuel.gazebosim.org/1.0/PX4/models/x500/meshes/rotor.dae</uri><scale>1 1 1</scale></mesh></geometry></visual><collision name="collision"><geometry><cylinder><radius>0.128</radius><length>0.005</length></cylinder></geometry></collision></link>
    <joint name="rotor_1_joint" type="revolute"><parent>base_link</parent><child>rotor_1</child><axis><xyz>0 0 1</xyz></axis></joint>

    <link name="rotor_2"><pose>0.13 0.22 0.023 0 0 0</pose><inertial><mass>0.005</mass><inertia><ixx>9.75e-07</ixx><iyy>0.0001667</iyy><izz>0.0001676</izz></inertia></inertial><visual name="visual"><geometry><mesh><uri>https://fuel.gazebosim.org/1.0/PX4/models/x500/meshes/rotor.dae</uri><scale>1 1 1</scale></mesh></geometry></visual><collision name="collision"><geometry><cylinder><radius>0.128</radius><length>0.005</length></cylinder></geometry></collision></link>
    <joint name="rotor_2_joint" type="revolute"><parent>base_link</parent><child>rotor_2</child><axis><xyz>0 0 1</xyz></axis></joint>

    <link name="rotor_3"><pose>-0.13 -0.2 0.023 0 0 0</pose><inertial><mass>0.005</mass><inertia><ixx>9.75e-07</ixx><iyy>0.0001667</iyy><izz>0.0001676</izz></inertia></inertial><visual name="visual"><geometry><mesh><uri>https://fuel.gazebosim.org/1.0/PX4/models/x500/meshes/rotor.dae</uri><scale>1 1 1</scale></mesh></geometry></visual><collision name="collision"><geometry><cylinder><radius>0.128</radius><length>0.005</length></cylinder></geometry></collision></link>
    <joint name="rotor_3_joint" type="revolute"><parent>base_link</parent><child>rotor_3</child><axis><xyz>0 0 1</xyz></axis></joint>
    
    <plugin filename="gz-sim-multicopter-motor-model-system" name="gz::sim::systems::MulticopterMotorModel"><jointName>rotor_0_joint</jointName><linkName>rotor_0</linkName><actuator_number>0</actuator_number><turningDirection>ccw</turningDirection></plugin>
    <plugin filename="gz-sim-multicopter-motor-model-system" name="gz::sim::systems::MulticopterMotorModel"><jointName>rotor_1_joint</jointName><linkName>rotor_1</linkName><actuator_number>1</actuator_number><turningDirection>cw</turningDirection></plugin>
    <plugin filename="gz-sim-multicopter-motor-model-system" name="gz::sim::systems::MulticopterMotorModel"><jointName>rotor_2_joint</jointName><linkName>rotor_2</linkName><actuator_number>2</actuator_number><turningDirection>ccw</turningDirection></plugin>
    <plugin filename="gz-sim-multicopter-motor-model-system" name="gz::sim::systems::MulticopterMotorModel"><jointName>rotor_3_joint</jointName><linkName>rotor_3</linkName><actuator_number>3</actuator_number><turningDirection>cw</turningDirection></plugin>

    <plugin filename="gz-sim-multicopter-control-system" name="gz::sim::systems::MulticopterVelocityControl">
      <comLinkName>base_link</comLinkName>
      <velocityGain>2.7 2.7 2.7</velocityGain>
      <attitudeGain>3.0 3.0 0.15</attitudeGain>
      <angularRateGain>0.52 0.52 0.025</angularRateGain>
      <rotorConfiguration>
        <rotor><joint_name>rotor_0_joint</joint_name><actuator_number>0</actuator_number><angle>-135</angle><direction>ccw</direction></rotor>
        <rotor><joint_name>rotor_1_joint</joint_name><actuator_number>1</actuator_number><angle>45</angle><direction>cw</direction></rotor>
        <rotor><joint_name>rotor_2_joint</joint_name><actuator_number>2</actuator_number><angle>135</angle><direction>ccw</direction></rotor>
        <rotor><joint_name>rotor_3_joint</joint_name><actuator_number>3</actuator_number><angle>-45</angle><direction>cw</direction></rotor>
      </rotorConfiguration>
    </plugin>

    <plugin filename="gz-sim-odometry-publisher-system" name="gz::sim::systems::OdometryPublisher"><odom_frame>odom</odom_frame><robot_base_frame>base_link</robot_base_frame><odom_topic>odometry</odom_topic></plugin>
  </model>
</sdf>