<?xml version="1.0" ?>
<sdf version="1.8">
  <model name="x500">
    <pose>0 0 0.194 0 0 0</pose>
    
    <!-- Base Link -->
    <link name="base_link">
      <pose>0 0 0 0 0 0</pose>
      <inertial>
        <mass>1.8</mass>
        <inertia>
          <ixx>0.0347563</ixx>
          <ixy>0</ixy>
          <ixz>0</ixz>
          <iyy>0.0458929</iyy>
          <iyz>0</iyz>
          <izz>0.0977</izz>
        </inertia>
      </inertial>

      <!-- Visual -->
      <visual name="visual">
        <geometry>
          <mesh>
            <uri>model://x500/meshes/x500.dae</uri>
            <scale>1 1 1</scale>
          </mesh>
        </geometry>
        <material>
          <ambient>0.5 0.5 0.5 1.0</ambient>
          <diffuse>0.7 0.7 0.7 1.0</diffuse>
          <specular>0.9 0.9 0.9 1.0</specular>
        </material>
      </visual>

      <!-- Collision -->
      <collision name="collision">
        <geometry>
          <box>
            <size>0.47 0.47 0.11</size>
          </box>
        </geometry>
      </collision>

      <!-- IMU Sensor -->
      <sensor name="imu_sensor" type="imu">
        <always_on>1</always_on>
        <update_rate>1000</update_rate>
        <visualize>true</visualize>
        <topic>imu</topic>
        <plugin filename="gz-sim-imu-system" name="gz::sim::systems::Imu">
        </plugin>
      </sensor>

      <!-- GPS Sensor -->
      <sensor name="gps_sensor" type="gps">
        <always_on>1</always_on>
        <update_rate>30</update_rate>
        <visualize>true</visualize>
        <topic>gps</topic>
        <plugin filename="gz-sim-navsat-system" name="gz::sim::systems::NavSat">
        </plugin>
      </sensor>
    </link>

    <!-- Rotor 0 (Front Right) -->
    <link name="rotor_0">
      <pose>0.13 -0.22 0.023 0 0 0</pose>
      <inertial>
        <mass>0.005</mass>
        <inertia>
          <ixx>9.75e-07</ixx>
          <iyy>0.000273104</iyy>
          <izz>0.000274004</izz>
        </inertia>
      </inertial>
      <visual name="visual">
        <geometry>
          <cylinder>
            <radius>0.1</radius>
            <length>0.005</length>
          </cylinder>
        </geometry>
        <material>
          <ambient>0.2 0.2 0.2 1.0</ambient>
          <diffuse>0.8 0.8 0.8 1.0</diffuse>
        </material>
      </visual>
    </link>

    <!-- Rotor 1 (Back Left) -->
    <link name="rotor_1">
      <pose>-0.13 0.2 0.023 0 0 0</pose>
      <inertial>
        <mass>0.005</mass>
        <inertia>
          <ixx>9.75e-07</ixx>
          <iyy>0.000273104</iyy>
          <izz>0.000274004</izz>
        </inertia>
      </inertial>
      <visual name="visual">
        <geometry>
          <cylinder>
            <radius>0.1</radius>
            <length>0.005</length>
          </cylinder>
        </geometry>
        <material>
          <ambient>0.2 0.2 0.2 1.0</ambient>
          <diffuse>0.8 0.8 0.8 1.0</diffuse>
        </material>
      </visual>
    </link>

    <!-- Rotor 2 (Front Left) -->
    <link name="rotor_2">
      <pose>0.13 0.22 0.023 0 0 0</pose>
      <inertial>
        <mass>0.005</mass>
        <inertia>
          <ixx>9.75e-07</ixx>
          <iyy>0.000273104</iyy>
          <izz>0.000274004</izz>
        </inertia>
      </inertial>
      <visual name="visual">
        <geometry>
          <cylinder>
            <radius>0.1</radius>
            <length>0.005</length>
          </cylinder>
        </geometry>
        <material>
          <ambient>0.2 0.2 0.2 1.0</ambient>
          <diffuse>0.8 0.8 0.8 1.0</diffuse>
        </material>
      </visual>
    </link>

    <!-- Rotor 3 (Back Right) -->
    <link name="rotor_3">
      <pose>-0.13 -0.2 0.023 0 0 0</pose>
      <inertial>
        <mass>0.005</mass>
        <inertia>
          <ixx>9.75e-07</ixx>
          <iyy>0.000273104</iyy>
          <izz>0.000274004</izz>
        </inertia>
      </inertial>
      <visual name="visual">
        <geometry>
          <cylinder>
            <radius>0.1</radius>
            <length>0.005</length>
          </cylinder>
        </geometry>
        <material>
          <ambient>0.2 0.2 0.2 1.0</ambient>
          <diffuse>0.8 0.8 0.8 1.0</diffuse>
        </material>
      </visual>
    </link>

    <!-- Joints -->
    <joint name="rotor_0_joint" type="revolute">
      <child>rotor_0</child>
      <parent>base_link</parent>
      <axis>
        <xyz>0 0 1</xyz>
        <limit>
          <lower>-1e+16</lower>
          <upper>1e+16</upper>
        </limit>
      </axis>
    </joint>

    <joint name="rotor_1_joint" type="revolute">
      <child>rotor_1</child>
      <parent>base_link</parent>
      <axis>
        <xyz>0 0 1</xyz>
        <limit>
          <lower>-1e+16</lower>
          <upper>1e+16</upper>
        </limit>
      </axis>
    </joint>

    <joint name="rotor_2_joint" type="revolute">
      <child>rotor_2</child>
      <parent>base_link</parent>
      <axis>
        <xyz>0 0 1</xyz>
        <limit>
          <lower>-1e+16</lower>
          <upper>1e+16</upper>
        </limit>
      </axis>
    </joint>

    <joint name="rotor_3_joint" type="revolute">
      <child>rotor_3</child>
      <parent>base_link</parent>
      <axis>
        <xyz>0 0 1</xyz>
        <limit>
          <lower>-1e+16</lower>
          <upper>1e+16</upper>
        </limit>
      </axis>
    </joint>

    <!-- Multirotor Plugin for Flight Control -->
    <plugin filename="gz-sim-multicopter-motor-model-system" name="gz::sim::systems::MulticopterMotorModel">
      <robotNamespace></robotNamespace>
      <jointName>rotor_0_joint</jointName>
      <linkName>rotor_0</linkName>
      <turningDirection>ccw</turningDirection>
      <timeConstantUp>0.0125</timeConstantUp>
      <timeConstantDown>0.025</timeConstantDown>
      <maxRotVelocity>1100</maxRotVelocity>
      <motorConstant>8.54858e-06</motorConstant>
      <momentConstant>0.06</momentConstant>
      <commandSubTopic>command/motor_speed</commandSubTopic>
      <motorNumber>0</motorNumber>
      <rotorDragCoefficient>0.000806428</rotorDragCoefficient>
      <rollingMomentCoefficient>1e-06</rollingMomentCoefficient>
      <motorSpeedPubTopic>motor_speed/0</motorSpeedPubTopic>
      <rotorVelocitySlowdownSim>10</rotorVelocitySlowdownSim>
    </plugin>

    <plugin filename="gz-sim-multicopter-motor-model-system" name="gz::sim::systems::MulticopterMotorModel">
      <robotNamespace></robotNamespace>
      <jointName>rotor_1_joint</jointName>
      <linkName>rotor_1</linkName>
      <turningDirection>ccw</turningDirection>
      <timeConstantUp>0.0125</timeConstantUp>
      <timeConstantDown>0.025</timeConstantDown>
      <maxRotVelocity>1100</maxRotVelocity>
      <motorConstant>8.54858e-06</motorConstant>
      <momentConstant>0.06</momentConstant>
      <commandSubTopic>command/motor_speed</commandSubTopic>
      <motorNumber>1</motorNumber>
      <rotorDragCoefficient>0.000806428</rotorDragCoefficient>
      <rollingMomentCoefficient>1e-06</rollingMomentCoefficient>
      <motorSpeedPubTopic>motor_speed/1</motorSpeedPubTopic>
      <rotorVelocitySlowdownSim>10</rotorVelocitySlowdownSim>
    </plugin>

    <plugin filename="gz-sim-multicopter-motor-model-system" name="gz::sim::systems::MulticopterMotorModel">
      <robotNamespace></robotNamespace>
      <jointName>rotor_2_joint</jointName>
      <linkName>rotor_2</linkName>
      <turningDirection>cw</turningDirection>
      <timeConstantUp>0.0125</timeConstantUp>
      <timeConstantDown>0.025</timeConstantDown>
      <maxRotVelocity>1100</maxRotVelocity>
      <motorConstant>8.54858e-06</motorConstant>
      <momentConstant>0.06</momentConstant>
      <commandSubTopic>command/motor_speed</commandSubTopic>
      <motorNumber>2</motorNumber>
      <rotorDragCoefficient>0.000806428</rotorDragCoefficient>
      <rollingMomentCoefficient>1e-06</rollingMomentCoefficient>
      <motorSpeedPubTopic>motor_speed/2</motorSpeedPubTopic>
      <rotorVelocitySlowdownSim>10</rotorVelocitySlowdownSim>
    </plugin>

    <plugin filename="gz-sim-multicopter-motor-model-system" name="gz::sim::systems::MulticopterMotorModel">
      <robotNamespace></robotNamespace>
      <jointName>rotor_3_joint</jointName>
      <linkName>rotor_3</linkName>
      <turningDirection>cw</turningDirection>
      <timeConstantUp>0.0125</timeConstantUp>
      <timeConstantDown>0.025</timeConstantDown>
      <maxRotVelocity>1100</maxRotVelocity>
      <motorConstant>8.54858e-06</motorConstant>
      <momentConstant>0.06</momentConstant>
      <commandSubTopic>command/motor_speed</commandSubTopic>
      <motorNumber>3</motorNumber>
      <rotorDragCoefficient>0.000806428</rotorDragCoefficient>
      <rollingMomentCoefficient>1e-06</rollingMomentCoefficient>
      <motorSpeedPubTopic>motor_speed/3</motorSpeedPubTopic>
      <rotorVelocitySlowdownSim>10</rotorVelocitySlowdownSim>
    </plugin>

    <!-- Multicopter Control Plugin -->
    <plugin filename="gz-sim-multicopter-control-system" name="gz::sim::systems::MulticopterVelocityControl">
      <robotNamespace></robotNamespace>
      <commandSubTopic>cmd_vel</commandSubTopic>
      <motorControlPubTopic>command/motor_speed</motorControlPubTopic>
      <enableSubTopic>enable</enableSubTopic>
      <comLinkName>base_link</comLinkName>
      <velocityGain>2.7 2.7 2.7</velocityGain>
      <attitudeGain>3.0 3.0 0.15</attitudeGain>
      <angularRateGain>0.4 0.4 0.4</angularRateGain>
      <maximumLinearAcceleration>2 2 2</maximumLinearAcceleration>
      <maximumLinearVelocity>5 5 5</maximumLinearVelocity>
      <maximumAngularVelocity>3 3 3</maximumAngularVelocity>
      <linearVelocityNoiseMean>0 0 0</linearVelocityNoiseMean>
      <linearVelocityNoiseStdDev>0.1 0.1 0.1</linearVelocityNoiseStdDev>
      <angularVelocityNoiseMean>0 0 0</angularVelocityNoiseMean>
      <angularVelocityNoiseStdDev>0.05 0.05 0.05</angularVelocityNoiseStdDev>
    </plugin>

    <!-- Odometry Plugin -->
    <plugin filename="gz-sim-odometry-publisher-system" name="gz::sim::systems::OdometryPublisher">
      <odom_frame>odom</odom_frame>
      <robot_base_frame>base_link</robot_base_frame>
      <odom_publish_frequency>50</odom_publish_frequency>
      <odom_topic>odometry</odom_topic>
    </plugin>

    <!-- Pose Publisher -->
    <plugin filename="gz-sim-pose-publisher-system" name="gz::sim::systems::PosePublisher">
      <publish_link_pose>true</publish_link_pose>
      <use_pose_vector_msg>true</use_pose_vector_msg>
      <static_publisher>true</static_publisher>
      <static_update_frequency>1</static_update_frequency>
    </plugin>

  </model>
</sdf>